<!DOCTYPE html>
<html><head>
  <title>防抖和节流案例</title>
  <meta charset="UTF-8">
  <style>
      *{margin:0;padding: 0;}
      body{height: 20000px;background: #ccc;}
  </style>
  </head>
<body>
<script>
//情景1
// var promiseF = new Promise((resolve, reject) => {
//     resolve('ok')
// })
// promiseF.then(result => {
//     return Promise.reject('error1')
// }).then(result => {
//     console.log(result) // 永远不会执行
//     return Promise.resolve('ok1') // 永远不会执行
// }).then(result => {
//     console.log(result) // 永远不会执行
// }).catch(error => {
//     console.log('error:',error) // error1
// })


//情景2
// function fetch() {
//     return new Promise((resolve, reject) => {
//         throw Error('用户不存在')
//     })
// }

// var t =  fetch('asdads')

// var tt = t.then(result => {
//     console.log('请求处理', result) // 永远不会执行
// }).catch(error => {
//     console.log('请求处理异常', error) // 请求处理异常 用户不存在
// })


//情景3
// function fetch() {
//     return new Promise((resolve, reject) => {
//           setTimeout(() => {
//              throw Error('用户不存在')
//         })
//     })
// }

// var t =  fetch('asdads')

// var tt = t.then(result => {
//     console.log('请求处理', result) // 永远不会执行
// }).catch(error => {
//     console.log('请求处理异常', error) //永远不会执行
// })


//情景4：
// Promise.resolve(true).then((resolve, reject)=> {
//     throw Error('microtask 中的异常')
// }).catch(error => {
//     console.log('捕获异常', error) // 捕获异常 Error: microtask 中的异常
// })

//情景5：
// function thirdFunction() {
//     setTimeout(() => {
//         throw Error('就是任性')
//     })
// }

// Promise.resolve(true).then((resolve, reject) => {
//     console.log(1);
//      thirdFunction()
// }).catch(error => {
//     console.log('捕获异常', error)
// })


//情景6：
function thirdFunction() {
    return new Promise((resolve, reject) => {
        setTimeout(() => {
            reject('收敛一些')
//             throw Error('就是任性')
        })
    })
}

Promise.resolve(true).then((resolve, reject) => {
    console.log(1);
    return thirdFunction() //return 很重要
    //then 会返回一个新的promise，其状态取决于then的返回值
    //如果 return thirdFunction() 这行缺少了 return 的话，依然无法抓住这个错误，
    //这是因为没有将对方返回的 Promise 传递下去，错误也不会继续传递。
}).catch(error => {
    console.log('捕获异常', error)
})

setTimeout(()=>{
    console.info(2);
},1000)
</script>



<script>
function thirdFunction() {
    return new Promise((resolve, reject) => {
        setTimeout(() => {
            reject('收敛一些'); //async可以捕获
//              throw Error('就是任性')//async无法捕获
        })
    })
}

async function main() {
    try {
        const result = await thirdFunction()
        console.log('请求处理', result) // 永远不会执行
    } catch (error) {
        console.log('异常', error) // 异常 收敛一些
    }
}

main()
</script>
</body>
</html>